<?xml version="1.0" ?>
<sdf version="1.8">
  <world name="maze_world">
    <plugin filename="gz-sim-physics-system" name="gz::sim::systems::Physics"></plugin>
    <plugin filename="gz-sim-user-commands-system" name="gz::sim::systems::UserCommands"></plugin>
    <plugin filename="gz-sim-scene-broadcaster-system" name="gz::sim::systems::SceneBroadcaster"></plugin>
    <plugin filename="gz-sim-sensors-system" name="gz::sim::systems::Sensors"></plugin>

    <light type="directional" name="sun">
      <cast_shadows>true</cast_shadows>
      <pose>0 0 10 0 0 0</pose>
      <diffuse>0.8 0.8 0.8 1</diffuse>
      <specular>0.2 0.2 0.2 1</specular>
      <attenuation>
        <range>1000</range>
        <constant>0.9</constant>
        <linear>0.01</linear>
        <quadratic>0.001</quadratic>
      </attenuation>
      <direction>-0.5 0.1 -0.9</direction>
    </light>

 <model name="ground_plane">
      <static>true</static>
      <link name="link">
        <collision name="collision">
          <geometry>
            <plane><normal>0 0 1</normal></plane>
          </geometry>
        </collision>
        <visual name="visual">
          <geometry>
            <plane><normal>0 0 1</normal><size>100 100</size></plane>
          </geometry>
        </visual>
      </link>
    </model>
 <model name="wall_1">
      <static>true</static>
      <pose>-3 0 0.5 0 0 0</pose>
      <link name="link">
        <collision name="collision"><geometry><box><size>0.2 4.0 1.0</size></box></geometry></collision>
        <visual name="visual"><geometry><box><size>0.2 4.0 1.0</size></box></geometry></visual>
      </link>
    </model>

    <model name="wall_2a">
      <static>true</static>
      <pose>0 2.2 0.5 0 0 0</pose>
      <link name="link">
        <collision name="collision"><geometry><box><size>3.0 0.2 1.0</size></box></geometry></collision>
        <visual name="visual"><geometry><box><size>3.0 0.2 1.0</size></box></geometry></visual>
      </link>
    </model>

    <model name="wall_2b">
      <static>true</static>
      <pose>2.5 2 0.5 0 0 0</pose>
      <link name="link">
        <collision name="collision"><geometry><box><size>1.0 0.2 1.0</size></box></geometry></collision>
        <visual name="visual"><geometry><box><size>1.0 0.2 1.0</size></box></geometry></visual>
      </link>
    </model>

    <model name="wall_3">
      <static>true</static>
      <pose>0 0 0.5 0 0 0</pose>
      <link name="link">
        <collision name="collision"><geometry><box><size>4.0 0.2 1.0</size></box></geometry></collision>
        <visual name="visual"><geometry><box><size>4.0 0.2 1.0</size></box></geometry></visual>
      </link>
    </model>

    <model name="wall_4">
      <static>true</static>
      <pose>3 0 0.5 0 0 0</pose>
      <link name="link">
        <collision name="collision"><geometry><box><size>0.2 4.0 1.0</size></box></geometry></collision>
        <visual name="visual"><geometry><box><size>0.2 4.0 1.0</size></box></geometry></visual>
      </link>
    </model>
 <model name="wall_5">
      <static>true</static>
      <pose>1 -1 0.5 0 0 0</pose>
      <link name="link">
        <collision name="collision"><geometry><box><size>2.0 0.2 1.0</size></box></geometry></collision>
        <visual name="visual"><geometry><box><size>2.0 0.2 1.0</size></box></geometry></visual>
      </link>
    </model>

    <model name="wall_6">
      <static>true</static>
      <pose>1 -2 0.5 0 0 0</pose>
      <link name="link">
        <collision name="collision"><geometry><box><size>5.0 0.2 1.0</size></box></geometry></collision>
        <visual name="visual"><geometry><box><size>5.0 0.2 1.0</size></box></geometry></visual>
      </link>
    </model>

    <model name="wall_7">
      <static>true</static>
      <pose>2 1.4 0.5 0 0 0</pose>
      <link name="link">
        <collision name="collision"><geometry><box><size>0.2 1.5 1.0</size></box></geometry></collision>
        <visual name="visual"><geometry><box><size>0.2 1.5 1.0</size></box></geometry></visual>
      </link>
    </model>

    <model name="wall_8">
      <static>true</static>
      <pose>-1.5 1.2 0.5 0 0 0</pose>
      <link name="link">
        <collision name="collision"><geometry><box><size>3.0 0.2 1.0</size></box></geometry></collision>
        <visual name="visual"><geometry><box><size>3.0 0.2 1.0</size></box></geometry></visual>
      </link>
    </model>
    <model name="wall_9">
      <static>true</static>
      <pose>-1.5 -1 0.5 0 0 0</pose>
      <link name="link">
        <collision name="collision"><geometry><box><size>1.5 0.2 1.0</size></box></geometry></collision>
        <visual name="visual"><geometry><box><size>1.5 0.2 1.0</size></box></geometry></visual>
      </link>
    </model>
<model name="my_robot">
      <pose>-2.5 -2.8 0.1 0 0 -1.5708</pose>

      <link name="chassis">
        <inertial><mass>5.0</mass></inertial>
        <collision name="collision"><geometry><box><size>0.4 0.2 0.1</size></box></geometry></collision>
        <visual name="visual">
          <geometry><box><size>0.4 0.2 0.1</size></box></geometry>
          <material><ambient>0 0 1 1</ambient><diffuse>0 0 1 1</diffuse></material>       
 </visual>
      </link>
      <link name="left_back_wheel">
        <pose>0.02 0.13 0 -1.5707 0 0</pose>
        <inertial>
          <mass>0.1</mass>
          <inertia>
            <ixx>0.00033</ixx><ixy>0</ixy><ixz>0</ixz>
            <iyy>0.00033</iyy><iyz>0</iyz>
            <izz>0.0005</izz>
          </inertia>
        </inertial>
        <collision name="collision"><geometry><cylinder><radius>0.1</radius><length>0.05</length></cylinder></geometry></collision>
        <visual name="visual">
          <geometry><cylinder><radius>0.1</radius><length>0.05</length></cylinder></geometry>
          <material><ambient>0 0 0 1</ambient><diffuse>0 0 0 1</diffuse></material>
        </visual>
      </link>

      <link name="right_back_wheel">
        <pose>0.02 -0.13 0 -1.5707 0 0</pose>
        <inertial>
          <mass>0.1</mass>
          <inertia>
            <ixx>0.00033</ixx><ixy>0</ixy><ixz>0</ixz>
            <iyy>0.00033</iyy><iyz>0</iyz>
            <izz>0.0005</izz>
          </inertia>
        </inertial>
        <collision name="collision"><geometry><cylinder><radius>0.1</radius><length>0.05</length></cylinder></geometry></collision>
        <visual name="visual">
  <geometry>
    <cylinder><radius>0.1</radius><length>0.04</length></cylinder>
  </geometry>
  <material><ambient>0 0 0 1</ambient><diffuse>0 0 0 1</diffuse></material>
</visual>
      </link>

 <link name="front_wheel">
  <pose>-0.15 0 0 -1.5707 0 0</pose>
  <inertial>
  <mass>0.1</mass>
  <inertia>
    <ixx>0.000076</ixx><ixy>0</ixy><ixz>0</ixz>
    <iyy>0.000076</iyy><iyz>0</iyz>
    <izz>0.000125</izz>
  </inertia>
</inertial>
 <collision name="collision">
    <geometry> 
      <cylinder>
        <radius>0.1</radius>
        <length>0.04</length>
      </cylinder>
    </geometry> 
  </collision>
  <visual name="visual">
    <geometry> 
      <cylinder>
        <radius>0.1</radius>
        <length>0.04</length>
      </cylinder>
    </geometry> 
    <material>
      <ambient>0 0 0 1</ambient>
      <diffuse>0 0 0 1</diffuse>
    </material>
  </visual>
</link>

      <link name="lidar_link">
        <pose>0 0 0.15 0 0 0</pose>
        <inertial><mass>0.1</mass></inertial>
        <collision name="collision"><geometry><cylinder><radius>0.05</radius><length>0.05</length></cylinder></geometry></collision>
        <visual name="visual">
          <geometry><cylinder><radius>0.05</radius><length>0.05</length></cylinder></geometry>
          <material><ambient>1 0 0 1</ambient><diffuse>1 0 0 1</diffuse></material>
        </visual>
        <sensor name="lidar" type="ray">
          <pose>0 0 0 0 0 0</pose>
          <always_on>true</always_on>
          <visualize>true</visualize>
          <update_rate>10</update_rate> 
          <topic>/scan</topic>
          <ray>
            <scan>
              <horizontal>
                <samples>360</samples>
                <resolution>1</resolution>
                <min_angle>-3.14159</min_angle>
                <max_angle>3.14159</max_angle>
              </horizontal>
            </scan>
            <range>
              <min>0.1</min>
              <max>10.0</max>
              <resolution>0.01</resolution>
            </range>
          </ray>
        </sensor>
      </link>

     <joint name="left_wheel_joint" type="revolute">
  <parent>chassis</parent>
  <child>left_back_wheel</child>
  <axis><xyz>0 0 1</xyz><limit><lower>-1.79769e+308</lower><upper>1.79769e+308</upper></limit></axis>
</joint>

<joint name="right_wheel_joint" type="revolute">
  <parent>chassis</parent>
  <child>right_back_wheel</child>
  <axis><xyz>0 0 1</xyz><limit><lower>-1.79769e+308</lower><upper>1.79769e+308</upper></limit></axis>
</joint>

<joint name="front_wheel_joint" type="revolute">
  <parent>chassis</parent>
  <child>front_wheel</child>
  <axis><xyz>0 0 1</xyz><limit><lower>-1.79769e+308</lower><upper>1.79769e+308</upper></limit></axis>
</joint>

<joint name="lidar_joint" type="fixed">
  <parent>chassis</parent>
  <child>lidar_link</child>
</joint>

<plugin filename="gz-sim-diff-drive-system" name="gz::sim::systems::DiffDrive">
  <left_joint>left_wheel_joint</left_joint>
  <right_joint>right_wheel_joint</right_joint>
  <wheel_separation>0.26</wheel_separation>
  <wheel_radius>0.1</wheel_radius>
  <odom_publish_frequency>1</odom_publish_frequency>
  <max_linear_acceleration>1</max_linear_acceleration>
  <min_linear_acceleration>-1</min_linear_acceleration>
  <max_angular_acceleration>2</max_angular_acceleration>
  <min_angular_acceleration>-2</min_angular_acceleration>
  <max_linear_velocity>0.5</max_linear_velocity>
  <min_linear_velocity>-0.5</min_linear_velocity>
  <topic>/cmd_vel</topic>
</plugin>
 </model>
</world>
</sdf>
