<sdf version="1.6">
  <world name="default">
    <include>
      <uri>model://sun</uri>
    </include>
    <include>
      <uri>model://ground_plane</uri>
    </include>
==============my robot================
<model name="my_robot">
  <static>false</static>
  <pose>-2.5 -2 0.10 0 0 1.5707</pose>

  <!-- CHASSIS -->
  <link name="chassis">
    <inertial>
      <mass>5.0</mass>
      <inertia>
        <ixx>0.047</ixx><ixy>0.0</ixy><ixz>0.0</ixz>
        <iyy>0.076</iyy><iyz>0.0</iyz>
        <izz>0.104</izz>
      </inertia>
    </inertial>
    </link>
    <collision name="collision">
      <geometry>
        <box><size>0.4 0.2 0.15</size></box>
      </geometry>
    </collision>
    <visual name="visual">
      <geometry>
        <box><size>0.4 0.2 0.15</size></box>
      </geometry>
      <material>
        <ambient>0 0 1 1</ambient>
        <diffuse>0 0 1 1</diffuse>
      </material>
    </visual>
  </link>

  <!-- LIDAR LINK (visual only, no sensor) -->
  <link name="lidar_link">
    <pose>0 0 0.1 0 0 0</pose>
    <inertial>
      <mass>0.1</mass>
      <inertia>
        <ixx>0.001</ixx><ixy>0.0</ixy><ixz>0.0</ixz>
        <iyy>0.001</iyy><iyz>0.0</iyz>
        <izz>0.001</izz>
      </inertia>
    </inertial>
    <collision name="lidar_collision">
      <geometry>
        <cylinder><radius>0.05</radius><length>0.05</length></cylinder>
      </geometry>
    </collision>
    <visual name="lidar_visual">
      <geometry>
        <cylinder><radius>0.05</radius><length>0.05</length></cylinder>
      </geometry>
    </visual>
  </link>

  <joint name="lidar_joint" type="fixed">
    <parent>chassis</parent>
    <child>lidar_link</child>
  </joint>

  <!-- LEFT WHEEL -->
  <link name="left_back_wheel">
    <pose>-0.05 0.15 0.015 1.5707 0 0</pose>
    <inertial>
     <pose>-0.05 0.15 0.015 1.5707 0 0</pose>
      <mass>0.5</mass>
      <inertia>
        <ixx>0.002</ixx><ixy>0.0</ixy><ixz>0.0</ixz>
        <iyy>0.002</iyy><iyz>0.0</iyz>
        <izz>0.004</izz>
      </inertia>
    </inertial>
  </link>
    <collision name="collision">
      <geometry>
        <cylinder><radius>0.1</radius><length>0.04</length></cylinder>
      </geometry>
      <surface>
        <friction>
          <ode><mu>1.0</mu><mu2>1.0</mu2></ode>
        </friction>
      </surface>
    </collision>
    <visual name="visual">
      <geometry>
        <cylinder><radius>0.1</radius><length>0.04</length></cylinder>
      </geometry>
      <material>
        <ambient>0 0 0 1</ambient>
        <diffuse>0 0 0 1</diffuse>
      </material>
    </visual>
  </link>

  <joint name="left_wheel_joint" type="revolute">
    <parent>chassis</parent>
    <child>left_back_wheel</child>
    <axis>
      <xyz>0 0 1</xyz>
    </axis>
  </joint>

  <!-- RIGHT WHEEL -->
  <link name="right_back_wheel">
    <pose>-0.05 -0.15 0.015 1.5707 0 0</pose>
    <inertial>
     <pose>-0.05 -0.15 0.015 1.5707 0 0</pose>
      <mass>0.5</mass>
      <inertia>
        <ixx>0.002</ixx><ixy>0.0</ixy><ixz>0.0</ixz>
        <iyy>0.002</iyy><iyz>0.0</iyz>
        <izz>0.004</izz>
      </inertia>
    </inertial>
    <collision name="collision">
      <geometry>
        <cylinder><radius>0.1</radius><length>0.04</length></cylinder>
      </geometry>
      <surface>
        <friction>
          <ode><mu>1.0</mu><mu2>1.0</mu2></ode>
        </friction>
      </surface>
    </collision>
    <visual name="visual">
      <geometry>
        <cylinder><radius>0.1</radius><length>0.04</length></cylinder>
      </geometry>
      <material>
        <ambient>0 0 0 1</ambient>
        <diffuse>0 0 0 1</diffuse>
      </material>
    </visual>
  </link>

  <joint name="right_wheel_joint" type="revolute">
    <parent>chassis</parent>
    <child>right_back_wheel</child>
    <axis>
      <xyz>0 0 1</xyz>
    </axis>
  </joint>

  <!-- FRONT CASTER -->
  <link name="front_wheel">
    <pose>0.15 0 -0.05 0 0 0</pose>
    <inertial>
      <mass>0.2</mass>
      <inertia>
        <ixx>0.001</ixx><ixy>0.0</ixy><ixz>0.0</ixz>
        <iyy>0.001</iyy><iyz>0.0</iyz>
        <izz>0.001</izz>
      </inertia>
    </inertial>
    <collision name="collision">
      <geometry>
        <sphere><radius>0.05</radius></sphere>
      </geometry>
      <surface>
        <friction>
          <ode><mu>0.0</mu><mu2>0.0</mu2></ode>
        </friction>
      </surface>
    </collision>
    <visual name="visual">
      <geometry>
        <sphere><radius>0.05</radius></sphere>
      </geometry>
      <material>
        <ambient>0.5 0.5 0.5 1</ambient>
        <diffuse>0.5 0.5 0.5 1</diffuse>
      </material>
    </visual>
  </link>

  <joint name="front_wheel_joint" type="ball">
    <parent>chassis</parent>
    <child>front_wheel</child>
  </joint>

  <!-- DIFF DRIVE PLUGIN -->
  <plugin filename="gz-sim-diff-drive-system" name="gz::sim::systems::DiffDrive">
    <left_joint>left_wheel_joint</left_joint>
    <right_joint>right_wheel_joint</right_joint>
    <wheel_separation>0.30</wheel_separation>
    <wheel_radius>0.1</wheel_radius>
    <odom_publish_frequency>10</odom_publish_frequency>
    <max_linear_velocity>0.5</max_linear_velocity>
    <min_linear_velocity>-0.5</min_linear_velocity>
    <max_angular_velocity>1.0</max_angular_velocity>
    <min_angular_velocity>-1.0</min_angular_velocity>
    <topic>/cmd_vel</topic>
  </plugin>

</model>
  </world>
</sdf>